<?xml version="1.0"?>
<robot name="ground_rover" xmlns:xacro="https://www.ros.org/wiki/xacro" >

    <link name="base_footprint" />

    <link name="base_link">
        <visual>
            <geometry>
                <mesh filename="file:/home/ubuntu20/Documents/simulation/meshes/Base_Assembly.dae" />
            </geometry>
            <origin xyz="0 0 0.02" rpy="0 0 0" />
        </visual>
    </link>

    <xacro:macro name="wheel_link" params="prefix yaw">
        <link name="${prefix}_wheel_link">
            <visual>
                <geometry>
                    <mesh filename="file:/home/ubuntu20/Documents/simulation/meshes/Wheel_Copy.dae" />
                </geometry>
                <origin xyz="0 0 0" rpy="0 0 ${yaw}" />
            </visual>
        </link>
    </xacro:macro>

    <xacro:macro name="wheel_joint" params="prefix x y">
        <joint name="base_${prefix}_wheel_joint" type="continuous">
            <parent link="base_link" />
            <child link="${prefix}_wheel_link" />
            <origin xyz="${x} ${y} 0" rpy="0 0 1.57" />
            <axis xyz="0 1 0" />
        </joint>
    </xacro:macro>

    <xacro:wheel_link prefix="left_back" yaw="0" />
    <xacro:wheel_link prefix="left_front" yaw="0" />
    <xacro:wheel_link prefix="right_back" yaw="3.14" />
    <xacro:wheel_link prefix="right_front" yaw="3.14" />

    <joint name="base_joint" type="fixed" >
        <parent link="base_footprint" />
        <child link="base_link" />
        <origin xyz="0 0 0.025" rpy="0 0 0" />
    </joint>

    <xacro:wheel_joint prefix="left_front" x="-0.0875" y="0.06" />
    <xacro:wheel_joint prefix="right_front" x="0.0875" y="0.06" />
    <xacro:wheel_joint prefix="left_back" x="-0.0875" y="-0.06" />
    <xacro:wheel_joint prefix="right_back" x="0.0875" y="-0.06" />
    
</robot>