<?xml version="1.0"?>
<robot name="ground_rover">

    <material name="grey">
        <color rgba="0.7 0.7 0.7 1" />
    </material>

    <material name="blue">
        <color rgba="0.15 0.15 0.2 1" />
    </material>

    <material name="white">
        <color rgba="1 1 1 1" />
    </material>

    <link name="base_footprint" />

    <link name="base_link">
        <inertial>
            <origin xyz="0.001 -0.003 -0.012" rpy="0 0 0" />
            <mass value="0.399" />
            <inertia ixx="0.001" ixy="-0.00" ixz="-0.00" iyy="0.001" iyz="0.00" izz="0.002" />
        </inertial>
        <visual>
            <geometry>
                <mesh filename="package://ground_rover/src/meshes/Base_Assembly.dae" />
            </geometry>
            <origin xyz="0 0 0.02" rpy="0 0 0" />
            <material name="blue" />
        </visual>
        <collision>
            <geometry>
                <box size="0.14 0.16 0.04" />
            </geometry>
            <origin xyz="0 0 0" rpy="0 0 0" />
        </collision>
    </link>

    <link name="left_back_wheel_link">
        <inertial>
            <origin xyz="-0.00 -0.002 0.00" rpy="0 0 0" />
            <mass value="0.062" />
            <inertia ixx="0.00" ixy="0.00" ixz="0.00" iyy="0.00" iyz="0.00" izz="0.00" />
        </inertial>
        <visual>
            <geometry>
                <mesh filename="package://ground_rover/src/meshes/Wheel_Copy.dae" />
            </geometry>
            <origin xyz="0 0 0" rpy="0 0 0" />
            <material name="grey" />
        </visual>
        <collision>
            <geometry>
                <cylinder radius="0.03" length="0.025" />
            </geometry>
            <origin xyz="0 0 0" rpy="1.57 0 0" />
        </collision>
    </link>

    <link name="left_front_wheel_link">
        <inertial>
            <origin xyz="-0.00 -0.002 0.00" rpy="0 0 0" />
            <mass value="0.062" />
            <inertia ixx="0.00" ixy="0.00" ixz="0.00" iyy="0.00" iyz="0.00" izz="0.00" />
        </inertial>
        <visual>
            <geometry>
                <mesh filename="package://ground_rover/src/meshes/Wheel_Copy.dae" />
            </geometry>
            <origin xyz="0 0 0" rpy="0 0 0" />
            <material name="grey" />
        </visual>
        <collision>
            <geometry>
                <cylinder radius="0.03" length="0.025" />
            </geometry>
            <origin xyz="0 0 0" rpy="1.57 0 0" />
        </collision>
    </link>

    <link name="right_back_wheel_link">
        <inertial>
            <origin xyz="-0.00 -0.002 0.00" rpy="0 0 0" />
            <mass value="0.062" />
            <inertia ixx="0.00" ixy="0.00" ixz="0.00" iyy="0.00" iyz="0.00" izz="0.00" />
        </inertial>
        <visual>
            <geometry>
                <mesh filename="package://ground_rover/src/meshes/Wheel_Copy.dae" />
            </geometry>
            <origin xyz="0 0 0" rpy="0 0 3.14" />
            <material name="grey" />
        </visual>
        <collision>
            <geometry>
                <cylinder radius="0.03" length="0.025" />
            </geometry>
            <origin xyz="0 0 0" rpy="1.57 0 0" />
        </collision>
    </link>

    <link name="right_front_wheel_link">
        <inertial>
            <origin xyz="-0.00 -0.002 0.00" rpy="0 0 0" />
            <mass value="0.062" />
            <inertia ixx="0.00" ixy="0.00" ixz="0.00" iyy="0.00" iyz="0.00" izz="0.00" />
        </inertial>
        <visual>
            <geometry>
                <mesh filename="package://ground_rover/src/meshes/Wheel_Copy.dae" />
            </geometry>
            <origin xyz="0 0 0" rpy="0 0 3.14" />
            <material name="grey" />
        </visual>
        <collision>
            <geometry>
                <cylinder radius="0.03" length="0.025" />
            </geometry>
            <origin xyz="0 0 0" rpy="1.57 0 0" />
        </collision>
    </link>

    <joint name="base_joint" type="fixed" >
        <parent link="base_footprint" />
        <child link="base_link" />
        <origin xyz="0 0 0.025" rpy="0 0 0" />
    </joint>

    <joint name="base_left_front_wheel_joint" type="continuous">
        <parent link="base_link" />
        <child link="left_front_wheel_link" />
        <origin xyz="-0.0875 0.06 0" rpy="0 0 1.57" />
        <axis xyz="0 1 0" />
    </joint>

    <joint name="base_right_front_wheel_joint" type="continuous">
        <parent link="base_link" />
        <child link="right_front_wheel_link" />
        <origin xyz="0.0875 0.06 0" rpy="0 0 1.57" />
        <axis xyz="0 1 0" />
    </joint>

    <joint name="base_left_back_wheel_joint" type="continuous">
        <parent link="base_link" />
        <child link="left_back_wheel_link" />
        <origin xyz="-0.0875 -0.06 0" rpy="0 0 1.57" />
        <axis xyz="0 1 0" />
    </joint>

    <joint name="base_right_back_wheel_joint" type="continuous">
        <parent link="base_link" />
        <child link="right_back_wheel_link" />
        <origin xyz="0.0875 -0.06 0" rpy="0 0 1.57" />
        <axis xyz="0 1 0" />
    </joint>
    
</robot>